Workbook

Sheet JAN
B1: JANUARY | K1: TECH REPORTS
A2: ANNUAL AGREEMENT SIGNED? | B2: FILE # | C2: CITY | D2: SERVICE TYPE | E2: # OF HRS REQ | F2: # OF TECHS | G2: STAMP/S REQ | H2: CONTRACTOR | I2: KEYS | J2: LAST COMPLETED | K2: REPORT IN EMAIL | L2: REPAIRS NEEDED | M2: REPORT COMPLETE | N2: ANNUAL REPORT SENT | O2: ASA sent | Q2: STAMP | R2: DEFINITION
A3: FALSE | B3: #0007 | C3: Vancouver | D3: Annual | E3: 3.5 | F3: 1 | G3: EX, EM | H3: No | I3: No | J3: Jan.06/26 | K3: TRUE | L3: TRUE | M3: TRUE | N3: TRUE | O3: TRUE
A4: FALSE | B4: #0011 | C4: Richmond | D4: Annual | E4: 1.2 | F4: 1 | G4: EX, EM | H4: No | I4: No | J4: 46059 | K4: TRUE | L4: FALSE | M4: FALSE | N4: FALSE | O4: FALSE | Q4: FA | R4: Fire Alarm
A5: FALSE | B5: #0060 | C5: Vancouver | D5: Annual | E5: 12 | F5: 2 | G5: FA, EX, EM, WA | H5: Yes | I5: Yes | J5: Jan 29-30/26 | K5: TRUE | L5: TRUE | M5: TRUE | N5: TRUE | O5: TRUE | P5: Report sent to PM by CG on Jan 31 | Q5: EX | R5: Fire Extinguisher
A6: FALSE | B6: #0082 | C6: Vancouver | D6: Annual | E6: 5.5 | F6: 2 | G6: FA, EX, EM, WA, BF | H6: No | I6: Yes | J6: Jan.20/26 | K6: TRUE | L6: TRUE | M6: TRUE | N6: TRUE | O6: TRUE | Q6: EM | R6: Emergency Lights
A7: FALSE | B7: #0116 | C7: Vancouver | D7: Annual | E7: 0.5 | F7: 1 | G7: EX | H7: No | I7: No | J7: 46034 | K7: TRUE | L7: FALSE | M7: TRUE | N7: TRUE | O7: FALSE | Q7: BF | R7: Backflow
A8: FALSE | B8: #0190 | C8: Vancouver | D8: Annual | E8: 8 | F8: 2 | G8: FA, WA, EX, EM, BF | H8: Yes | I8: No | J8: CLOSED | K8: FALSE | L8: FALSE | M8: FALSE | N8: FALSE | O8: FALSE | P8: CLOSED | Q8: SM | R8: Smoke Control
A9: FALSE | B9: #0207 | C9: Vancouver | D9: Annual | E9: 1.5 | F9: 1 | G9: EX, EM, BF | H9: No | I9: No | J9: 46052 | K9: TRUE | L9: FALSE | M9: TRUE | N9: TRUE | O9: FALSE | R9: STAMPS HELD | V9: Proceedure:
A10: TRUE | B10: #0209 | C10: Vancouver | D10: Annual minus DPV | E10: 8 | F10: 3 | G10: FA, WA, EX, EM, BF | H10: Yes | I10: No | J10: Jan.7/26 | K10: TRUE | L10: TRUE | M10: TRUE | N10: TRUE | O10: TRUE | Q10: RS | R10: FA, WA, EX, EM | V10: When you open file to schedule a month, first highlight all
A11: FALSE | B11: #0220 | C11: Vancouver | D11: Annual | E11: 1.5 | F11: 1 | G11: WA, EX | H11: No | I11: No | J11: 46041 | K11: TRUE | L11: FALSE | M11: TRUE | N11: TRUE | O11: FALSE | Q11: CY | R11: FA, WA, EX, EM | V11: the current year then change to yellow. Once job is
A12: FALSE | B12: #0255 | C12: Vancouver | D12: Annual | E12: 0.5 | F12: 1 | G12: EX | H12: No | I12: No | J12: Jan 12/ 26 | K12: TRUE | L12: TRUE | M12: TRUE | N12: TRUE | O12: TRUE | Q12: MV | R12: FA, WA, EX, EM, BF & FITTER | V12: completed then change to green or blue if only partially
A13: FALSE | B13: #0350 | C13: Vancouver | D13: Annual | E13: 1.5 | F13: 2 | G13: FA, EX, EM | H13: No | I13: No | J13: 46080 | K13: TRUE | L13: TRUE | M13: TRUE | N13: TRUE | O13: TRUE | Q13: GW | R13: FA, WA, EX, EM
A14: TRUE | B14: #0358 | C14: Vancouver | D14: Annual | E14: 3 | F14: 2 | G14: FA, WA, EX, EM | H14: No | I14: Yes | J14: Jan.30/26 | K14: TRUE | L14: TRUE | M14: TRUE | N14: TRUE | O14: TRUE | Q14: TS | R14: EX, EM, BF
A15: FALSE | B15: #0401 | C15: Vancouver | D15: Annual | E15: 1 | F15: 1 | G15: EX, EM | H15: No | I15: No | J15: 46041 | K15: TRUE | L15: FALSE | M15: TRUE | N15: TRUE | O15: FALSE
A16: FALSE | B16: #0437 | C16: Burnaby | D16: Annual | E16: 3 | F16: 2 | G16: FA, EX, EM | H16: No | I16: Yes | J16: Jan.19/26 | K16: TRUE | L16: TRUE | M16: TRUE | N16: TRUE | O16: TRUE | Q16: COLOUR CODE | U16: Responsibility
A17: FALSE | B17: #0441 | C17: Surrey | D17: Annual | E17: 1.5 | F17: 1 | G17: EX, EM | H17: No | I17: No | J17: 46013 | K17: TRUE | L17: FALSE | M17: TRUE | N17: TRUE | O17: TRUE | Q17: DUE | R17: Needs To Be Scheduled | T17: ## | U17: Scheduling Department
A18: FALSE | B18: #0461 | C18: Vancouver | D18: Annual minus BF & DPV | E18: 6 | F18: 2 | G18: FA, WA, EX, EM | H18: Yes | I18: Yes | J18: CLOSED | K18: FALSE | L18: FALSE | M18: FALSE | N18: FALSE | O18: FALSE | P18: was scheduled & confirmed by onsite then PM emailed and cancelled FILE CLOSED JULY 2025 | Q18: SCHEDULED | R18: Scheduled & Confirmed | T18: ## | U18: Scheduling Department
Q19: SEMI-COMPLETE | R19: Revisit Required To Complete Service | T19: ## | U19: Invoicing Department
A20: FALSE | B20: #0516 | C20: Vancouver | D20: Annual minus DPV | E20: 16 | F20: 3 | G20: FA, WA, EX, EM, BF | H20: Yes | I20: Yes | J20: Feb 23-24, 2026 | K20: TRUE | L20: TRUE | M20: TRUE | N20: TRUE | O20: FALSE | Q20: COMPLETE | R20: Service 100% Complete | T20: ## | U20: Invoicing Department
A21: TRUE | B21: #0518 | C21: Surrey | D21: Annual minus DPV | E21: 40 | F21: 2 | G21: FA, WA, EX, EM, BF | H21: No | I21: No | J21: Jan.12-16/26 | K21: TRUE | L21: TRUE | M21: TRUE | N21: TRUE | O21: TRUE
A22: FALSE | B22: #0529 | C22: Vancouver | D22: Annual | E22: 4.5 | F22: 2 | G22: FA, EX, EM | H22: Yes | I22: No | J22: 46041 | K22: FALSE | L22: FALSE | M22: FALSE | N22: FALSE | O22: FALSE | P22: POSTPONED
A23: FALSE | B23: #0540 | C23: Vancouver | D23: Annual | E23: 0.5 | F23: 1 | G23: EX | H23: No | I23: No | J23: Jan.12/26 | K23: TRUE | L23: FALSE | M23: TRUE | N23: TRUE | O23: FALSE
A24: FALSE | B24: #0559 | C24: Coquitlam | D24: Hydrants | H24: Yes | I24: No | J24: Jan 24, 24 | K24: FALSE | L24: FALSE | M24: FALSE | N24: FALSE | O24: FALSE | Q24: TOTAL REMAINING LABOUR HOURS | S24: =#REF!-AUG!R24 -> #REF!
A25: TRUE | B25: #0583 | C25: Vancouver | D25: Annual minus DPV & Kitchen | E25: 7.5 | F25: 2 | G25: FA, EX, EM, BF | H25: Yes | I25: Yes | J25: 46045 | K25: TRUE | L25: TRUE | M25: TRUE | N25: TRUE | O25: TRUE
A26: TRUE | B26: #0586 | C26: Vancouver | D26: Annual | E26: 3.5 | F26: 2 | G26: FA, WA, EX, EM, BF | H26: Yes | I26: Yes | J26: Feb.27/26 | K26: FALSE | L26: FALSE | M26: FALSE | N26: FALSE | O26: FALSE
A27: FALSE | B27: #0603 | C27: Vancouver | D27: Annual | E27: 1 | F27: 1 | G27: EX, EM | H27: No | I27: No | J27: CANCELLED | K27: FALSE | L27: FALSE | M27: FALSE | N27: FALSE | O27: FALSE
A28: FALSE | B28: #0636 | C28: Richmond | D28: Annual | E28: 1.5 | F28: 1 | G28: EX, EM | H28: No | I28: No | J28: 46034 | K28: TRUE | L28: FALSE | M28: TRUE | N28: TRUE | O28: FALSE
A29: TRUE | B29: #0645 | C29: Vancouver | D29: Annual | E29: 7 | F29: 2 | G29: FA, EX, EM, BF(JULY) | H29: No | I29: No | J29: 46045 | K29: TRUE | L29: TRUE | M29: TRUE | N29: TRUE | O29: TRUE
A30: FALSE | B30: #0661 | C30: North Vancouver | D30: Monthly | E30: 2 | F30: 1 | G30: FA, WA, EX, EM | H30: No | I30: Yes | J30: 46028 | K30: TRUE | L30: FALSE | M30: FALSE | N30: FALSE | O30: FALSE
A31: TRUE | B31: #0696 | C31: Vancouver | D31: Annual minus DPV | E31: 8 | F31: 2 | G31: FA, WA EX, EM | H31: Yes | I31: Yes | J31: 46048 | K31: TRUE | L31: TRUE | M31: TRUE | N31: TRUE | O31: FALSE
A32: TRUE | B32: #0705 | C32: Vancouver | D32: Annual | E32: 1 | F32: 1 | G32: EX | H32: No | I32: No | J32: Jan.19/26 | K32: FALSE | L32: FALSE | M32: FALSE | N32: FALSE | O32: FALSE
A33: FALSE | B33: #0755 | D33: Annual | E33: 1 | F33: 1 | G33: WA | H33: No | I33: No | J33: 46049 | K33: TRUE | L33: FALSE | M33: FALSE | N33: FALSE | O33: FALSE
A34: FALSE | B34: #0764 | C34: SURREY | D34: Annual | E34: 8 | F34: 2 | J34: 46057 | K34: TRUE | L34: TRUE | M34: TRUE | N34: TRUE | O34: TRUE
A35: FALSE | B35: #0468 | C35: DELTA | D35: Annual | E35: 3 | F35: 1 | G35: EX, EM, BF | H35: No | I35: No | J35: 46030 | K35: TRUE | L35: FALSE | M35: TRUE | N35: TRUE | O35: FALSE
A36: FALSE | B36: #0801 | D36: Annual | E36: 1 | F36: 1 | G36: SA | H36: No | I36: No | K36: FALSE | L36: FALSE | M36: FALSE | N36: FALSE | O36: FALSE | P36: was OTC038
E38: =SUM(E2:E36) -> 163.7

Sheet FEB
B1: FEBRUARY | K1: TECH REPORTS
A2: ANNUAL AGREEMENT SIGNED? | B2: FILE # | C2: CITY | D2: SERVICE TYPE | E2: # OF HRS REQ | F2: # OF TECHS | G2: STAMP/S REQ | H2: CONTRACTOR | I2: KEYS | J2: LAST COMPLETED | K2: REPORT IN EMAIL | L2: REPAIRS NEEDED | M2: REPORT COMPLETE | N2: ANNUAL REPORT SENT | O2: ASA sent | Q2: STAMP | R2: DEFINITION
A3: FALSE | B3: #0025 | C3: Vancouver | D3: Annual minus DPV | E3: 8 | F3: 2 | G3: FA, EX, EM, WA | H3: Yes | I3: Yes | J3: Feb.17/26 | K3: TRUE | L3: TRUE | M3: TRUE | N3: TRUE | O3: TRUE | Q3: FA | R3: Fire Alarm
A4: FALSE | B4: #0026 | C4: Vancouver | D4: Annual | E4: 3 | F4: 2 | G4: EX, EM, WA | H4: No | I4: No | J4: 46059 | K4: TRUE | L4: TRUE | M4: TRUE | N4: TRUE | O4: TRUE | Q4: WA | R4: Sprinkler
A5: FALSE | B5: #0037 | C5: Vancouver | D5: AnnuaL | E5: 8 | F5: 2 | G5: FA, EX, EM, WA | H5: Yes | I5: No | J5: 46072 | K5: TRUE | L5: TRUE | M5: TRUE | N5: TRUE | O5: TRUE | Q5: EX | R5: Fire Extinguisher
A6: TRUE | B6: #0042 | C6: Richmond | D6: Annual | E6: 1.5 | F6: 2 | G6: FE | H6: No | I6: No | J6: 46066 | K6: TRUE | L6: TRUE | M6: TRUE | N6: TRUE | O6: TRUE | Q6: EM | R6: Emergency Lights
A7: FALSE | B7: #0054 | C7: Vancouver | D7: Annual + Spring as of 2025 | E7: 20 | F7: 2 | G7: FA, EX, EM, WA, BF | H7: Yes | I7: Yes | J7: Feb.11-13/26 | K7: TRUE | L7: TRUE | M7: TRUE | N7: TRUE | O7: FALSE | Q7: BF | R7: Backflow
A8: TRUE | B8: #0079 | C8: Vancouver | D8: Annual | E8: 3 | F8: 2 | G8: FA, FE, EL, WA, BF | H8: No | I8: No | J8: 46066 | K8: TRUE | L8: TRUE | M8: TRUE | N8: TRUE | O8: TRUE | Q8: SM | R8: Smoke Control
A9: FALSE | B9: #0202 | C9: Vancouver | D9: Annual | E9: 3.5 | F9: 2 | G9: FA, WA, EX, EM, BF | H9: No | I9: Yes | J9: Feb 6/ 26 | K9: TRUE | L9: TRUE | M9: TRUE | N9: TRUE | O9: TRUE
A10: FALSE | B10: #0221 | C10: Vancouver | D10: Annual | E10: 1 | F10: 2 | G10: FA | H10: No | I10: No | J10: 46056 | K10: TRUE | L10: TRUE | M10: TRUE | N10: TRUE | O10: TRUE | Q10: TECH | R10: STAMPS HELD
A11: FALSE | B11: #0270 | C11: Vancouver | D11: Kitchen | E11: 1 | F11: 1 | G11: FA | H11: Yes | I11: Yes | J11: 45716 | K11: FALSE | L11: FALSE | M11: FALSE | N11: FALSE | O11: FALSE | Q11: =#REF! -> #REF! | R11: =#REF! -> #REF!
A12: FALSE | B12: #0301 | C12: Vancouver | D12: Annual | E12: 8 | F12: 2 | G12: FA, WA, EX, EM, BF | H12: No | I12: Yes | J12: 46058 | K12: TRUE | L12: TRUE | M12: TRUE | N12: TRUE | O12: FALSE | Q12: =JAN!Q11 -> CY | R12: =JAN!R11 -> FA, WA, EX, EM
A13: TRUE | B13: #0326 | C13: West Vancouver | D13: Annual | E13: 24 | F13: 2 | G13: FA, WA, EX, EM | H13: No | I13: Yes | J13: Feb 2-4th/26 | K13: TRUE | L13: TRUE | M13: TRUE | N13: TRUE | O13: FALSE | Q13: =JAN!Q12 -> MV | R13: =JAN!R12 -> FA, WA, EX, EM, BF & FITTER
A14: TRUE | B14: #0360 | C14: Vancouver | D14: Annual + Wet - Dry | E14: 38 | F14: 3 | G14: FA, WA EX, EM, BF | H14: Yes | I14: Yes | J14: Feb.23-26/26 | K14: TRUE | L14: TRUE | M14: TRUE | N14: TRUE | O14: TRUE | Q14: =#REF! -> #REF! | R14: =#REF! -> #REF!
A15: TRUE | B15: #0409 | C15: Coquitlam | D15: Annual | E15: 6.5 | F15: 2 | G15: FA, WA, EX, EM | H15: No | I15: No | J15: 46064 | K15: TRUE | L15: TRUE | M15: TRUE | N15: TRUE | O15: TRUE | Q15: =#REF! -> #REF! | R15: =#REF! -> #REF!
A16: FALSE | B16: #0413 | C16: New Westminster | D16: Annual | E16: 24 | F16: 2 | G16: FA, WA, EX, EM, BF | H16: Yes | I16: Yes | J16: Mar 4-6/26 | K16: TRUE | L16: TRUE | M16: TRUE | N16: TRUE | O16: TRUE | Q16: =JAN!Q13 -> GW | R16: =JAN!R13 -> FA, WA, EX, EM
A17: FALSE | B17: #0438 | C17: Richmond | D17: Suppression | H17: Yes | I17: No | J17: Mar 22, 24 | K17: FALSE | L17: FALSE | M17: FALSE | N17: FALSE | O17: FALSE | P17: Waiting for quote for repair from Acme | Q17: =JAN!Q14 -> TS | R17: =JAN!R14 -> EX, EM, BF
A18: FALSE | B18: #0460 | C18: Burnaby | D18: Annual | E18: 12 | F18: 2 | G18: FA, EX, EM, BF | H18: No | I18: Yes | J18: FEb 10-11/26 | K18: FALSE | L18: FALSE | M18: FALSE | N18: FALSE | O18: FALSE
A19: FALSE | B19: #0468 | C19: Delta | D19: Annual | E19: 3 | F19: 1 | G19: EX, EM, BF | H19: No | I19: No | J19: 46030 | K19: TRUE | L19: FALSE | M19: FALSE | N19: FALSE | O19: FALSE | P19: see Jan tab
A20: FALSE | B20: #0469 | C20: Surrey | D20: Annual | E20: 1 | F20: 1 | G20: EX, EM | H20: No | I20: No | J20: Dec 22/ 25 | K20: FALSE | L20: FALSE | M20: FALSE | N20: FALSE | O20: FALSE | P20: see Jan tab | Q20: COLOUR CODE | U20: Responsibility
A21: FALSE | B21: #0538 | C21: Vancouver | D21: Annual | E21: 8 | F21: 2 | G21: FA, WA, EX, EM, BF | H21: No | I21: Yes | J21: Feb 11/ 26 | K21: TRUE | L21: TRUE | M21: TRUE | N21: TRUE | O21: FALSE | Q21: DUE | R21: Needs To Be Scheduled | T21: ## | U21: Scheduling Department
A22: FALSE | B22: #0538 | C22: Vancouver | D22: Annual | E22: 4.5 | F22: 2 | G22: FA, WA, EX, EM, BF | H22: No | I22: Yes | J22: - | K22: FALSE | L22: FALSE | M22: FALSE | N22: FALSE | O22: FALSE | Q22: SCHEDULED | R22: Scheduled & Confirmed | T22: ## | U22: Scheduling Department
A23: FALSE | B23: #0649 | C23: Vancouver | D23: Annual | E23: 1 | F23: 1 | G23: EX, EM | H23: No | I23: No | J23: Mar.05/25 | K23: FALSE | L23: FALSE | M23: FALSE | N23: FALSE | O23: FALSE | P23: no charge c/o RS | Q23: SEMI-COMPLETE | R23: Revisit Required To Complete Service | T23: ## | U23: Invoicing Department
A24: FALSE | B24: #0661 | C24: North Vancouver | D24: Monthly | E24: 2 | F24: 1 | G24: FA, WA, EX, EM | H24: No | I24: Yes | J24: Feb.3/26 | K24: TRUE | L24: FALSE | M24: FALSE | N24: FALSE | O24: FALSE | Q24: COMPLETE | R24: Service 100% Complete | T24: ## | U24: Invoicing Department
A25: TRUE | B25: #0686 | C25: Vancouver | D25: Annual | E25: 6 | F25: 2 | G25: FA, WA, EX, EM, BF | H25: No | I25: No | J25: Feb.9/26 | K25: TRUE | L25: FALSE | M25: TRUE | N25: TRUE | O25: FALSE | Q25: TOTAL LABOUR HRS: | R25: =(E3*F3)+(E4*F4)+(E5*F5)+(E6*F6)+(E7*F7)+(E8*F8)+(#REF!*#REF!)+(DEC!E10*DEC!F10)+(E9*F9)+(E10*F10)+(#REF!*#REF!)+(E11*F11)+(E12*F12)+(E13*F13)+(E14*F14)+(E15*F15)+(E16*F16)+(E17*F17)+(E18*F18)+(E19*F19)+(E20*F20)+(E21*F21)+(E22*F22)+(E23*F23)+(E24*F24)+(#REF!*#REF!)+(E25*F25)+(E26*F26)+(E27*F27)+(E28*F28)+(E29*F29)+(E31*F31)+(E32*F32)+(E33*F33)+(E34*F34)+(E35*F35)+(E36*F36)+(E37*F37)+(E44*F39)+(E40*F40)+(E41*F41)+(E42*F42)+(E43*F43)+(#REF!*F44)+(E45*F45)+(E46*F46)+(E47*F47)+(E48*F48)+(E49*F49)+(E50*F50)+(E51*F51)+(E52*F52)+(E53*F53)+(E54*F54)+(E55*F55)+(E56*F56)+(E57*F57)+(E58*F58)+(E59*F59)+(E60*F60)+(E61*F61)+(E62*F62)+(E63*F63)+(E64*F64)+(E65*F65)+(E66*F66)+(E67*F67)+(E68*F68)+(E69*F69)+(E70*F70)+(E71*F71)+(E72*F72)+(E73*F73)+(E74*F74)+(E75*F75)+(E76*F76)+(E77*F77)+(E78*F78)+(E79*F79)+(E80*F80)+(E81*F81)+(E82*F82)+(E83*F83)+(E84*F84)+(E85*F85)+(E86*F86)+(E87*F87)+(E88*F88)+(E89*F89)+(E90*F90)+(E91*F91)+(E92*F92)+(E93*F93)+(E94*F94)+(E95*F95)+(E96*F96)+(E97*F97)+(E98*F98)+(E99*F99)+(E100*F100) -> #REF!
A26: TRUE | B26: #0687 | C26: Vancouver | D26: Annual | E26: 3.5 | F26: 2 | G26: FA, EX, EM, BF | H26: No | I26: No | J26: 46066 | K26: TRUE | L26: FALSE | M26: FALSE | N26: FALSE | O26: FALSE
A27: TRUE | B27: #0688 | C27: Vancouver | D27: Annual | E27: 2.5 | F27: 2 | G27: FA, EX, EM, BF | H27: No | I27: No | J27: Feb 9/ 26 | K27: TRUE | L27: TRUE | M27: TRUE | N27: TRUE | O27: TRUE | Q27: TOTAL AVAILABLE LABOUR HOURS IN THE MONTH | T27: 640 | V27: Based on 4 Techs in the field. Derived by (days of month divided by 7 then times by 5) x (number of techs times by 8)
A28: FALSE | B28: #0725 | C28: Port Coquitlam | D28: Annual & Hydrants | E28: 16 | F28: 2 | G28: FA, WA, EX, EM | H28: Yes | I28: Yes | J28: CLOSED | K28: TRUE | L28: TRUE | M28: TRUE | N28: TRUE | O28: TRUE
A29: FALSE | B29: #0748 | C29: Richmond | D29: Annual | E29: 0.5 | F29: 1 | G29: EX | H29: No | I29: No | J29: Feb.28/25 | K29: TRUE | L29: FALSE | M29: TRUE | N29: TRUE | O29: FALSE | Q29: REMAINING LABOUR HRS | S29: =T27-R25 -> #REF!
A30: FALSE | B30: #0755 | D30: Annual | E30: 1 | F30: 1 | G30: WA | H30: No | I30: No | J30: 45709 | K30: TRUE | L30: TRUE | M30: TRUE | N30: TRUE | O30: TRUE
A31: FALSE | B31: #0761 | C31: Vancouver | D31: Annual | E31: 1 | F31: 1 | G31: EX, EM | H31: No | I31: No | J31: 46056 | K31: TRUE | L31: FALSE | M31: TRUE | N31: TRUE | O31: FALSE
A32: FALSE | B32: #0781 | C32: Vancouver | D32: Annual | E32: 16 | F32: 2 | G32: FA, EX, EM, DPV, WA, BF | H32: YES, KITCHEN | I32: NO | J32: 46071 | K32: TRUE | L32: TRUE | M32: TRUE | N32: TRUE | O32: FALSE | P32: Kitchen done on Jan 13, 2026
A33: FALSE | B33: #0786 | C33: Vancouver | D33: Annual | E33: 24 | F33: 3 | J33: Feb.17-19/26 | K33: TRUE | L33: TRUE | M33: TRUE | N33: TRUE | O33: FALSE
A34: FALSE | B34: #0798 | C34: Vancouver | D34: Annual | F34: 1 | G34: EX, EM, BF | H34: No | I34: No | J34: new. Due in 2026 | K34: FALSE | L34: FALSE | M34: FALSE | N34: FALSE | O34: FALSE | P34: was OTC043
A35: FALSE | B35: #0765 | C35: Vancouver | D35: Annual | E35: 1 | F35: 1 | G35: EX, EM | H35: No | I35: No | J35: Feb.21/25 | K35: FALSE | L35: FALSE | M35: FALSE | N35: FALSE | O35: FALSE
A36: FALSE | B36: #0772 | C36: Vancouver | D36: BF | G36: BF | H36: No | K36: FALSE | L36: FALSE | M36: FALSE | N36: FALSE | O36: FALSE
A37: FALSE | B37: #0330-2 | C37: Vancouver | D37: Annual | G37: EX | H37: No | K37: FALSE | L37: FALSE | M37: FALSE | N37: FALSE | O37: FALSE
A38: FALSE | B38: #0817 | C38: Vancouver | D38: Annual | E38: 1 | F38: 1 | G38: EX | H38: No | I38: No | J38: 46056 | K38: TRUE | L38: TRUE | M38: TRUE | N38: TRUE | O38: TRUE
A39: FALSE | B39: #0818 | C39: Vancouver | D39: Annual | E39: 1 | F39: 1 | G39: EX, EL | H39: No | I39: No | J39: 46080 | K39: TRUE | L39: FALSE | M39: TRUE | N39: TRUE | O39: FALSE
E44: =SUM(E2:E39) -> 254.5

Sheet MAR
B1: MARCH | K1: TECH REPORTS
A2: ANNUAL AGREEMENT SIGNED? | B2: FILE # | C2: CITY | D2: SERVICE TYPE | E2: # OF HRS REQ | F2: # OF TECHS | G2: STAMP/S REQ | H2: CONTRACTOR | I2: KEYS | J2: LAST COMPLETED | K2: REPORT IN EMAIL | L2: REPAIRS NEEDED | M2: REPORT COMPLETE | N2: ANNUAL REPORT SENT | O2: ASA sent | Q2: STAMP | R2: DEFINITION
A3: TRUE | B3: #0032 | C3: Vancouver | D3: Annual | E3: 8 | F3: 2 | G3: FA, EX, EM, WA, BF | H3: Yes | I3: No | J3: 46086 | K3: TRUE | L3: TRUE | M3: TRUE | N3: TRUE | O3: FALSE | Q3: FA | R3: Fire Alarm
A4: FALSE | B4: #0047 | C4: North Vancouver | D4: Annual | E4: 5.5 | F4: 2 | G4: FA, EX, EM, WA | H4: Yes | I4: Yes | J4: 46087 | K4: TRUE | L4: TRUE | M4: TRUE | N4: TRUE | O4: FALSE
A5: FALSE | B5: #0094 | C5: Vancouver | D5: Annual | E5: 2 | F5: 1 | G5: EX, WA | H5: No | I5: No | J5: 45364 | K5: FALSE | L5: FALSE | M5: FALSE | N5: FALSE | O5: FALSE | P5: Russ only | Q5: EX | R5: Fire Extinguisher
A6: FALSE | B6: #0098 | C6: Vancouver | D6: Annual | E6: 6 | F6: 2 | G6: FA, WA | H6: Yes | I6: Yes | J6: 46093 | K6: TRUE | L6: TRUE | M6: TRUE | N6: TRUE | O6: FALSE | P6: tech report emailed april 28/25 | Q6: EM | R6: Emergency Lights
A7: FALSE | B7: #0114 | C7: Vancouver | D7: Annual | E7: 1 | F7: 1 | G7: EM | H7: No | I7: No | J7: Apr.10/25 | K7: FALSE | L7: FALSE | M7: FALSE | N7: FALSE | O7: FALSE | Q7: BF | R7: Backflow
A8: FALSE | B8: #0199 | C8: Vancouver | D8: Annual - Odd years only | E8: 1.5 | F8: 1 | G8: WA, EX | H8: No | I8: No | J8: Declined | K8: FALSE | L8: FALSE | M8: FALSE | N8: FALSE | O8: FALSE | P8: will call to schedule for April 2025 | Q8: SM | R8: Smoke Control
A9: FALSE | B9: #0203 | C9: Vancouver | D9: Annual | E9: 2.5 | F9: 2 | G9: FA, EX, EM | H9: No | I9: Yes | J9: 46113 | K9: FALSE | L9: FALSE | M9: FALSE | N9: FALSE | O9: FALSE
A10: TRUE | B10: #0216 | C10: Vancouver | D10: Annual | E10: 2.5 | F10: 2 | G10: FA, EX, EM, BF | H10: No | I10: Yes | J10: Mar.17/26 | K10: FALSE | L10: FALSE | M10: FALSE | N10: FALSE | O10: FALSE | Q10: TECH | R10: STAMPS HELD
A11: FALSE | B11: #0248 | C11: Richmond | D11: Hydrant | E11: 0 | F11: 0 | G11: - | H11: Yes | I11: No | J11: 45364 | K11: FALSE | L11: FALSE | M11: FALSE | N11: FALSE | O11: FALSE | Q11: =#REF! -> #REF! | R11: =#REF! -> #REF!
A12: FALSE | B12: #0259 | C12: Vancouver | D12: Annual | E12: 1 | F12: 1 | G12: EX, EM | H12: No | I12: No | J12: Mar.20/25 | K12: FALSE | L12: FALSE | M12: FALSE | N12: FALSE | O12: FALSE
A13: FALSE | B13: #0281 | C13: Burnaby | D13: Annual | E13: 2.5 | F13: 2 | G13: FA, WA | H13: No | I13: No | J13: 46091 | K13: TRUE | L13: TRUE | M13: TRUE | N13: TRUE | O13: TRUE | Q13: =#REF! -> #REF! | R13: =JAN!R9 -> STAMPS HELD
A14: TRUE | B14: #0308 | C14: Vancouver | D14: Annual | E14: 2.5 | F14: 2 | G14: FA, EX, EM | H14: No | I14: Yes | J14: Mar.13/25 | K14: FALSE | L14: FALSE | M14: FALSE | N14: FALSE | O14: FALSE | Q14: =JAN!Q10 -> RS | R14: =JAN!R10 -> FA, WA, EX, EM
A15: FALSE | B15: #0327 | C15: Vancouver | D15: Annual | E15: 7.5 | F15: 2 | G15: FA, WA, EX, EM, BF | H15: No | I15: Yes | J15: 46092 | K15: TRUE | L15: TRUE | M15: TRUE | N15: TRUE | O15: FALSE | Q15: =#REF! -> #REF! | R15: =#REF! -> #REF!
A16: FALSE | B16: #0349 | C16: Vancouver | D16: Kitchen | E16: 0 | F16: 0 | H16: Yes | J16: Mar.06/25 | K16: FALSE | L16: FALSE | M16: FALSE | N16: FALSE | O16: FALSE | P16: Normally scheduled in September | Q16: =JAN!Q11 -> CY | R16: =JAN!R11 -> FA, WA, EX, EM
A17: FALSE | B17: #0371 | C17: Vancouver | D17: Annual | F17: 2 | G17: FA, EX, BF | H17: No | I17: No | J17: 46113 | K17: TRUE | L17: FALSE | M17: FALSE | N17: FALSE | O17: FALSE | P17: Russ only | Q17: =JAN!Q12 -> MV | R17: =JAN!R12 -> FA, WA, EX, EM, BF & FITTER
A18: TRUE | B18: #0397 | C18: Vancouver | D18: Annual | E18: 23 | F18: 2 | G18: FA, WA, EX, EM, BF | H18: Yes | I18: Yes | J18: May 6-7, 2026 | K18: FALSE | L18: FALSE | M18: FALSE | N18: FALSE | O18: FALSE | Q18: =#REF! -> #REF! | R18: =#REF! -> #REF!
A19: FALSE | B19: #0402 | C19: Bowen Island | D19: Annual | F19: 2 | G19: FA, WA, EX, EM, BF | H19: No | I19: No | J19: CLOSING FILE | K19: FALSE | L19: FALSE | M19: FALSE | N19: FALSE | O19: FALSE | Q19: =#REF! -> #REF! | R19: =#REF! -> #REF!
A20: FALSE | B20: #0408 | C20: New Westminster | D20: Annual | E20: 40 | F20: 3 | G20: FA, WA, EX, EM, BF | H20: Yes | I20: Yes | J20: Mar 16-23/26 | K20: TRUE | L20: TRUE | M20: TRUE | N20: TRUE | O20: FALSE
A21: FALSE | B21: #0412 | C21: Vancouver | D21: Annual | G21: WA, EX | H21: No | I21: No | J21: Feb28, 24 | K21: FALSE | L21: FALSE | M21: FALSE | N21: FALSE | O21: FALSE | P21: delaying inspection a few weeks, contact in April
A22: FALSE | B22: #0444 | C22: Vancouver | D22: Suppression & Wet Sprinkler | E22: 2 | F22: 1 | G22: FA, WA | H22: Yes | I22: No | J22: 45351 | K22: FALSE | L22: FALSE | M22: FALSE | N22: FALSE | O22: FALSE | P22: waiting for quote from Acme for suppression repair | Q22: COLOUR CODE | U22: Responsibility
A23: FALSE | B23: #0449 | C23: Vancouver | D23: Annual | E23: 2.5 | F23: 1 | G23: WA, EX, BF | H23: No | I23: No | J23: Feb 26, 24 | K23: FALSE | L23: FALSE | M23: FALSE | N23: FALSE | O23: FALSE | P23: emailed 3 times and l/m, no response | Q23: DUE | R23: Needs To Be Scheduled | T23: ## | U23: Scheduling Department
A24: FALSE | B24: #0477 | C24: Vancouver | D24: Annual | E24: 4 | F24: 2 | G24: FA, WA, EX, EM | H24: No | I24: No | J24: 46090 | K24: TRUE | L24: TRUE | M24: TRUE | N24: TRUE | O24: FALSE | Q24: SCHEDULED | R24: Scheduled & Confirmed | T24: ## | U24: Scheduling Department
A25: FALSE | B25: #0478 | C25: Richmond | D25: Annual | E25: 16 | F25: 2 | G25: FA, WA, EX, EM | H25: No | I25: Yes | J25: Mar 11 & 13/26 | K25: TRUE | L25: TRUE | M25: TRUE | N25: TRUE | O25: TRUE | Q25: SEMI-COMPLETE | R25: Revisit Required To Complete Service | T25: ## | U25: Invoicing Department
A26: TRUE | B26: #0521 | C26: Burnaby | D26: Annual minus DPV | E26: 12 | F26: 2.5 | G26: FA, WA, EX, EM, BF | H26: Yes | I26: Yes | J26: Mar 2-3/26 | K26: TRUE | L26: TRUE | M26: TRUE | N26: TRUE | O26: TRUE | Q26: COMPLETE | R26: Service 100% Complete | T26: ## | U26: Invoicing Department
A27: FALSE | B27: #0542 | C27: West Vancouver | D27: Annual | E27: 4.5 | F27: 2 | G27: FA, WA, EX, EM, BF | H27: Yes | I27: Yes | J27: 46126 | K27: FALSE | L27: FALSE | M27: FALSE | N27: FALSE | O27: FALSE
A28: FALSE | B28: #0543 | C28: Vancouver | D28: Annual | E28: 1 | F28: 1 | G28: EX | H28: No | I28: No | J28: 46090 | K28: TRUE | L28: TRUE | M28: TRUE | N28: TRUE | O28: TRUE
A29: FALSE | B29: #0556 | C29: Vancouver | D29: Annual | E29: 1 | F29: 1 | G29: EX, EM | H29: No | I29: No | J29: 46087 | K29: TRUE | L29: FALSE | M29: TRUE | N29: TRUE | O29: FALSE | Q29: TOTAL LABOUR HRS: | R29: =(E3*F3)+(#REF!*#REF!)+(E5*F5)+(E6*F6)+(E7*F7)+(E8*F8)+(E10*F10)+(E11*F11)+(E13*F13)+(E14*F14)+(E15*F15)+(E16*F16)+(E17*F17)+(E18*F18)+(E19*F19)+(E20*F20)+(E21*F21)+(E22*F22)+(E23*F23)+(E24*F24)+(E25*F25)+(E26*F26)+(E27*F27)+(E28*F28)+(E29*F29)+(E30*F30)+(#REF!*#REF!)+(E31*F31)+(E33*F33)+(E34*F34)+(E35*F35)+(E36*F36)+(#REF!*#REF!)+(#REF!*#REF!)+(#REF!*#REF!)+(#REF!*#REF!)+(E37*F37)+(E38*F38)+(E39*F39)+(E40*F40)+(E41*F41)+(E42*F42)+(E43*F43)+(E44*F44)+(E45*F45)+(E46*F46)+(#REF!*#REF!)+(E47*F47)+(E48*F48)+(E49*F49)+(E50*F50)+(E52*F52)+(E56*F56)+(E57*F57)+(E58*F58)+(E59*F59)+(E60*F60)+(E61*F61)+(E62*F62)+(E63*F63)+(E64*F64)+(E65*F65)+(E66*F66)+(E67*F67)+(E68*F68)+(E69*F69)+(E70*F70)+(E71*F71)+(E72*F72)+(E73*F73)+(E74*F74)+(E75*F75)+(E76*F76)+(E77*F77)+(E78*F78)+(E79*F79)+(E80*F80)+(E81*F81)+(E82*F82)+(E83*F83)+(E84*F84)+(E85*F85)+(E86*F86)+(E87*F87)+(E88*F88)+(E89*F89)+(E90*F90)+(E91*F91)+(E92*F92)+(E93*F93)+(E94*F94)+(E95*F95)+(E96*F96)+(E97*F97)+(E98*F98) -> #REF!
A30: TRUE | B30: #0583 | C30: Vancouver | D30: Spring & Kitchen | E30: 4 | F30: 2 | G30: FA, WA | H30: Yes | I30: Yes | J30: 46052 | K30: FALSE | L30: FALSE | M30: FALSE | N30: FALSE | O30: FALSE
A31: FALSE | B31: #0661 | C31: North Vancouver | D31: Monthly | E31: 2 | F31: 1 | G31: FA, WA, EX, EM | H31: No | I31: Yes | J31: 46093 | K31: TRUE | L31: FALSE | M31: FALSE | N31: FALSE | O31: FALSE | Q31: REMAINING LABOUR HRS | S31: =T34-R29 -> #REF!
A32: FALSE | B32: #0678 | C32: Vancouver | D32: Annual minus DPV | E32: 3.5 | F32: 2 | G32: FA, EX, EM | H32: No | I32: Yes | J32: CLOSED | K32: FALSE | L32: FALSE | M32: FALSE | N32: FALSE | O32: FALSE | P32: Closed file on July 29, 2025
A33: FALSE | B33: #0724 | C33: Vancouver | D33: Annual | E33: 1.5 | F33: 1 | G33: FA, EX, EM | H33: No | I33: No | J33: 46091 | K33: TRUE | L33: FALSE | M33: FALSE | N33: FALSE | O33: FALSE
A34: FALSE | B34: #0749 | C34: Richmond | D34: Annual | E34: 2 | F34: 1 | G34: EX, EM | H34: No | I34: No | J34: Yvonne Denied March Annual | K34: FALSE | L34: FALSE | M34: FALSE | N34: FALSE | O34: FALSE | Q34: TOTAL AVAILABLE LABOUR HOURS IN THE MONTH | T34: 708 | V34: Based on 4 Techs in the field. Derived by (days of month divided by 7 then times by 5) x (number of techs times by 8)
A35: FALSE | B35: #0750 | C35: Vancouver | D35: Annual | E35: 3 | F35: 2 | G35: FA, EX, EM | H35: No | I35: No | J35: 46091 | K35: TRUE | L35: TRUE | M35: TRUE | N35: TRUE | O35: TRUE
A36: FALSE | B36: #0769 | C36: Burnaby | D36: Annual | E36: 1 | F36: 1 | G36: EX, EM | H36: No | I36: No | J36: 45364 | K36: FALSE | L36: FALSE | M36: FALSE | N36: FALSE | O36: FALSE | P36: Emailed & sent quote - no response
A37: FALSE | B37: #0470-1 | C37: Burnaby | D37: ANNUAL | E37: 3 | F37: 1 | G37: EX | H37: No | I37: No | J37: Mar.18/25 | K37: FALSE | L37: FALSE | M37: FALSE | N37: FALSE | O37: FALSE | P37: Emailed no response
A38: FALSE | B38: #0726 | C38: Vancouver | D38: ANNUAL | E38: 1 | F38: 1 | G38: EX, EM | H38: No | I38: No | J38: 46090 | K38: TRUE | L38: FALSE | M38: TRUE | N38: TRUE | O38: FALSE | P38: As per CY, 5 of 6 FX were serviced by Executive Fire and due for service in Oct, 2026. He only serviced 1 FX.
A39: FALSE | B39: #0787 | C39: Vancouver | D39: ANNUAL | E39: 3 | F39: 2 | G39: FA, FE, EL | H39: NO | I39: NO | J39: 46119 | K39: FALSE | L39: FALSE | M39: FALSE | N39: FALSE | O39: FALSE | P39: emailed
A40: FALSE | B40: #0788 | C40: Vancouver | D40: ANNUAL | E40: 3 | F40: 2 | G40: FA, FE, EL | H40: NO | I40: NO | J40: Mar.06/25 | K40: FALSE | L40: FALSE | M40: FALSE | N40: FALSE | O40: FALSE | P40: --
...

Sheet APR
B1: APRIL | K1: TECH REPORTS
A2: ANNUAL AGREEMENT SIGNED? | B2: FILE # | C2: CITY | D2: SERVICE TYPE | E2: # OF HRS REQ | F2: # OF TECHS | G2: STAMP/S REQ | H2: CONTRACTOR | I2: KEYS | J2: LAST COMPLETED | K2: REPORT IN EMAIL | L2: REPAIRS NEEDED | M2: REPORT COMPLETE | N2: ANNUAL REPORT SENT | O2: ASA Sent | P2: INVOICE AMOUNT | R2: STAMP | S2: DEFINITION
A3: FALSE | B3: #0054 | C3: Vancouver | D3: Annual | E3: 13 | F3: 2 | G3: FA, EX, EM, WA | H3: Yes | I3: Yes | J3: Feb.26,27 &Mar.19/25 | K3: TRUE | L3: TRUE | M3: TRUE | N3: TRUE | O3: TRUE | Q3: Moved to Feb tab | R3: FA | S3: Fire Alarm
A4: TRUE | B4: #0061 | C4: Vancouver | D4: Annual | E4: 11.5 | F4: 2 | G4: FA, EX, EM, WA | H4: Yes | I4: Yes | J4: Sep 15-16, 2025 | K4: TRUE | L4: TRUE | M4: TRUE | N4: TRUE | O4: TRUE | Q4: Moved to Sept tab | R4: WA | S4: Sprinkler
A5: FALSE | B5: #0062 | C5: Richmond | D5: Annual | E5: 6 | F5: 2 | G5: FA, WA, BF | H5: Yes | I5: No | J5: DECLINED USED ANOTHER COMPANY | K5: FALSE | L5: FALSE | M5: FALSE | N5: FALSE | O5: FALSE | Q5: acct closed | R5: EX | S5: Fire Extinguisher
A6: FALSE | B6: #0100 | C6: Vancouver | D6: Annual | E6: 4 | F6: 2 | G6: FA, EX, EM, WA, BF | H6: No | I6: Yes | J6: 45791 | K6: TRUE | L6: TRUE | M6: TRUE | N6: TRUE | O6: TRUE | R6: EM | S6: Emergency Lights
A7: FALSE | B7: #0107 | C7: Vancouver | D7: Backflow & DPV Spring | E7: 2.5 | F7: 2 | G7: WA, BF | H7: Yes | I7: Yes | J7: 45783 | K7: TRUE | L7: TRUE | M7: TRUE | N7: TRUE | O7: TRUE | R7: BF | S7: Backflow
A8: FALSE | B8: #0127 | C8: Vancouver | D8: Annual | E8: 2 | F8: 2 | G8: FA, EX, EM | H8: No | I8: No | J8: 45779 | K8: TRUE | L8: TRUE | M8: TRUE | N8: TRUE | O8: TRUE | Q8: no report rec'd from tech
A9: TRUE | B9: #0175 | C9: Vancouver | D9: Annual | E9: 3 | F9: 2 | G9: FA, WA, EX, EM | H9: No | I9: Yes | J9: Mar.26/25 | K9: TRUE | L9: TRUE | M9: TRUE | N9: TRUE | O9: TRUE | R9: SM | S9: Smoke Control
A10: FALSE | B10: #0189 | C10: Vancouver | D10: Annual | E10: 2 | F10: 1 | G10: EX | H10: No | I10: No | J10: Apr.10/25 | K10: TRUE | L10: FALSE | M10: TRUE | N10: TRUE | O10: FALSE
A11: FALSE | B11: #0208 | C11: Vancouver | D11: Annual | E11: 6 | F11: 2 | G11: FA, WA, EX, EM | H11: Yes | I11: Yes | J11: 45778 | K11: TRUE | L11: FALSE | M11: FALSE | N11: FALSE | O11: FALSE | R11: TECH | S11: STAMPS HELD
A12: TRUE | B12: #0240 | C12: Vancouver | D12: Annual minus DPV | E12: 36 | F12: 3 | G12: FA, EX, EM, BF | H12: Yes | I12: Yes | J12: Apr 14,15,16/25 | K12: TRUE | L12: TRUE | M12: TRUE | N12: TRUE | O12: TRUE
A13: FALSE | K13: FALSE | L13: FALSE | M13: FALSE | N13: FALSE | O13: FALSE
A14: FALSE | B14: #0271 | C14: Vancouver | D14: Annual | E14: 6 | F14: 2 | G14: FA, EX, EM, BF | H14: No | I14: Yes | J14: 45779 | K14: TRUE | L14: TRUE | M14: TRUE | N14: TRUE | O14: TRUE | R14: RS | S14: FA, WA, EX, EM
A15: FALSE | B15: #0276 | C15: Vancouver | D15: Annual | E15: 2 | F15: 1 | G15: EX, EM | H15: No | I15: No | J15: 45744 | K15: TRUE | L15: TRUE | M15: TRUE | N15: TRUE | O15: TRUE | R15: CG | S15: FA, WA, EX, EM, BF, SM
A16: FALSE | B16: #0293 | C16: Vancouver | D16: Annual | E16: 12 | F16: 2 | G16: FA, WA, EX, EM, BF | H16: Yes | I16: Yes | J16: Apr.23, 24/25 | K16: TRUE | L16: TRUE | M16: TRUE | N16: TRUE | O16: TRUE | R16: CY | S16: FA, WA, EX, EM
A17: FALSE | B17: #0320 | C17: Vancouver | D17: Annual | E17: 8 | F17: 2 | G17: FA, WA, EX, EM | H17: Yes | I17: Yes | J17: Apr.28,29/25 | K17: TRUE | L17: TRUE | M17: TRUE | N17: TRUE | O17: TRUE | R17: MV | S17: FA, WA, EX, EM, BF & FITTER
A18: TRUE | B18: #0323 | C18: Vancouver | D18: Annual + Kitchen | E18: 20 | F18: 2 | G18: FA, WA, EX, EM, BF | H18: Yes | I18: Yes | J18: May 5-9,25 | K18: TRUE | L18: TRUE | M18: TRUE | N18: TRUE | O18: FALSE | R18: PM | S18: FA, WA, EX, EM
A19: TRUE | B19: #0329 | C19: Vancouver | D19: Annual | E19: 6 | F19: 2 | G19: FA, WA, EX, EM, BF | H19: Yes | I19: No | J19: 45785 | K19: TRUE | L19: TRUE | M19: TRUE | N19: TRUE | O19: TRUE | R19: RD | S19: TRAINEE
A20: TRUE | B20: #0330 | C20: Vancouver | D20: EX, DPV Spring, Hydrant & BF | E20: 5 | F20: 2 | G20: FA, WA, EX, BF | H20: Yes | I20: No | J20: 45782 | K20: FALSE | L20: FALSE | M20: FALSE | N20: FALSE | O20: FALSE | R20: GW | S20: FA, WA, EX, EM
A21: TRUE | B21: #0330-1 | C21: Vancouver | D21: Spring | E21: 1.5 | F21: 1 | G21: WA, BF | H21: No | I21: No | J21: 45782 | K21: FALSE | L21: FALSE | M21: FALSE | N21: FALSE | O21: FALSE
A22: TRUE | B22: #0334 | C22: Burnaby | D22: Annual | E22: 6 | F22: 1 | G22: EX, EM | H22: No | I22: No | J22: 45866 | K22: TRUE | L22: TRUE | M22: TRUE | N22: TRUE | O22: TRUE
A23: FALSE | B23: #0415 | C23: Vancouver | D23: Annual | E23: 6 | F23: 2 | G23: FA, WA, EX, EM, BF | H23: No | I23: No | J23: CLOSED | K23: FALSE | L23: FALSE | M23: FALSE | N23: FALSE | O23: FALSE | R23: COLOUR CODE | V23: Responsibility
A24: FALSE | B24: #0442 | C24: Burnaby | D24: Annual | E24: 16 | F24: 2 | H24: Yes | I24: Yes | J24: May 12,13/25 | K24: TRUE | L24: TRUE | M24: TRUE | N24: TRUE | O24: TRUE | R24: DUE | S24: Needs To Be Scheduled | U24: ## | V24: Scheduling Department
A25: FALSE | B25: #0467 | C25: Vancouver | D25: Annual | E25: 2 | F25: 1 | G25: WA, EX, EM, BF | H25: No | I25: No | J25: CLOSED | K25: TRUE | L25: TRUE | M25: TRUE | N25: TRUE | O25: TRUE | R25: SCHEDULED | S25: Scheduled & Confirmed | U25: ## | V25: Scheduling Department
A26: FALSE | B26: #0513 | C26: Vancouver | D26: Annual | E26: 8 | F26: 2 | G26: FA, WA, EX, EM, BF | H26: Yes | I26: Yes | J26: 45790 | K26: TRUE | L26: TRUE | M26: TRUE | N26: TRUE | O26: TRUE | R26: SEMI-COMPLETE | S26: Revisit Required To Complete Service | U26: ## | V26: Invoicing Department
A27: TRUE | B27: #0521 | C27: Burnaby | D27: Kitchen & DPV | E27: 6 | F27: 2 | G27: FA, WA | H27: Yes | I27: Yes | J27: w/annual Mar 13 2025 | K27: TRUE | L27: TRUE | M27: TRUE | N27: TRUE | O27: TRUE | R27: COMPLETE | S27: Service 100% Complete | U27: ## | V27: Invoicing Department
A28: FALSE | B28: #0569 | C28: Vancouver | D28: Spring | E28: 2 | F28: 1 | G28: FA, WA | H28: Yes | I28: Yes | J28: 45783 | K28: FALSE | L28: FALSE | M28: FALSE | N28: FALSE | O28: FALSE | R28: TOTAL LABOUR HOURS: | S28: =(E3*F3)+(E4*F4)+(E5*F5)+(E6*F6)+(E7*F7)+(E8*F8)+(E9*F9)+(E10*F10)+(E11*F11)+(E14*F14)+(E15*F15)+(E16*F16)+(E17*F17)+(E18*F18)+(E19*F19)+(E20*F20)+(E21*F21)+(E22*F22)+(E23*F23)+(E24*F24)+(E25*F25)+(E26*F26)+(E27*F27)+(E28*F28)+(E29*F29)+(E30*F30)+(E31*F31)+(E32*F32)+(E33*F33)+(E34*F34)+(E35*F35)+(E36*F36)+(E37*F37)+(E38*F38)+(E39*F39)+(E40*F40)+(E41*F41)+(E42*F42)+(E43*F43)+(E44*F44)+(E45*F45)+(E46*F46)+(E47*F47)+(E48*F48)+(E49*F49)+(E50*F50)+(E51*F51)+(E52*F52)+(E53*F53)+(E54*F54)+(E55*F55)+(E56*F56)+(E57*F57)+(E58*F58)+(E59*F59)+(E60*F60)+(E61*F61)+(E62*F62)+(E63*F63)+(E64*F64)+(E65*F65)+(E66*F66)+(E67*F67)+(E68*F68)+(E69*F69)+(E70*F70)+(E71*F71)+(E72*F72)+(E73*F73)+(E74*F74)+(E75*F75)+(E76*F76)+(E77*F77)+(E78*F78)+(E79*F79)+(E80*F80)+(E81*F81)+(E82*F82)+(E83*F83)+(E84*F84)+(E85*F85)+(E86*F86)+(E87*F87)+(E88*F88)+(E89*F89)+(E90*F90)+(E91*F91)+(E92*F92)+(E93*F93)+(E94*F94)+(E95*F95)+(E96*F96)+(E97*F97)+(E98*F98)+(E99*F99)+(E100*F100)+(E101*F101) -> 502
A29: FALSE | B29: #0609 | C29: Vancouver | D29: Annual | E29: 8 | F29: 2 | G29: FA, WA, EX, EM, BF | H29: Yes | I29: Yes | J29: 45784 | K29: TRUE | L29: TRUE | M29: TRUE | N29: TRUE | O29: TRUE
A30: FALSE | B30: #0646 | C30: Vancouver | D30: Annual | E30: 16 | F30: 2 | G30: FA, WA, EX, EM, BF | H30: Yes | I30: Yes | J30: CLOSED | K30: TRUE | L30: TRUE | M30: TRUE | N30: TRUE | O30: TRUE
A31: FALSE | B31: #0652 | C31: Vancouver | D31: Annual | E31: 8 | F31: 2 | G31: FA, WA, EX, EM | H31: No | I31: Yes | J31: CLOSED | K31: TRUE | L31: TRUE | M31: TRUE | N31: TRUE | O31: TRUE
A32: FALSE | B32: #0661 | C32: North Vancouver | D32: Monthly | E32: 2 | F32: 1 | G32: FA, WA, EX, EM | H32: No | I32: Yes | J32: Apr.1/25 | K32: FALSE | L32: FALSE | M32: FALSE | N32: FALSE | O32: FALSE
A33: TRUE | B33: #0674 | C33: Vancouver | D33: Annual | E33: 8 | F33: 2 | G33: FA, WA, EX, EM, BF | H33: Yes | I33: Yes | J33: 46094 | K33: TRUE | L33: TRUE | M33: TRUE | N33: TRUE | O33: FALSE | Q33: REQUIRES 1 MONTHS NOTICE!
A34: FALSE | B34: #0728 | C34: Vancouver | D34: Annual | E34: 2 | F34: 1 | G34: WA, BF | H34: No | I34: No | J34: Apr.9/25 | K34: TRUE | L34: FALSE | M34: FALSE | N34: TRUE | O34: FALSE | Q34: BF
A35: FALSE | B35: #0751 | C35: Vancouver | D35: Annual | E35: 2.5 | F35: 1 | G35: EX, EM | H35: No | I35: No | J35: 45814 | K35: TRUE | L35: FALSE | M35: TRUE | N35: TRUE | O35: FALSE
A36: FALSE | B36: #0752 | C36: Vancouver | D36: Annual | E36: 4 | F36: 2 | G36: FA, EX, EM | H36: No | I36: No | J36: 45877 | K36: TRUE | L36: TRUE | M36: TRUE | N36: TRUE | O36: TRUE
A37: FALSE | B37: #0765 | C37: Vancouver | D37: Annual | E37: 1 | F37: 1 | G37: EX, EM | H37: No | I37: No | J37: Feb.21/25 | K37: TRUE | L37: FALSE | M37: TRUE | N37: TRUE | O37: FALSE
A38: FALSE | B38: #0766 | C38: New Westminster | D38: Annual | E38: 6 | F38: 2 | G38: FA, EX, EM, WA | H38: No | I38: No | J38: 45772 | K38: TRUE | L38: TRUE | M38: TRUE | N38: TRUE | O38: TRUE
A39: FALSE | B39: #0767 | C39: New Westminster | D39: Annual | E39: 8 | F39: 2 | G39: FA, EX, EM | J39: 45786 | K39: TRUE | L39: TRUE | M39: TRUE | N39: TRUE | O39: TRUE
A40: FALSE | B40: #0771 | C40: Vancouver | D40: Annual | E40: 1 | F40: 1 | G40: EX, EM | H40: No | I40: No | J40: Apr 29, 24. No response | K40: FALSE | L40: FALSE | M40: FALSE | N40: FALSE | O40: FALSE
...

Sheet SPRING
B1: SPRING (Late March to Late August) (ENSURE 2ND TECH FOR FULL TRIP OR EXCESIVE LP's) | J1: TECH REPORTS
A2: 2025 AUDIT DONE ?- Y/N | B2: FILE # | C2: SERVICE TYPE | D2: # OF HRS REQ | E2: # OF TECHS | F2: STAMP/S REQ | G2: CONTRACTOR | H2: KEYS | I2: LAST COMPLETED | J2: REPORT IN EMAIL | K2: REPAIRS NEEDED | L2: REPORT COMPLETE | N2: STAMP | O2: DEFINITION
A3: Y | B3: #0020 | C3: DPV | D3: 4 | E3: 2 | F3: WA | G3: Yes | H3: Yes | I3: 45818 | J3: TRUE | K3: FALSE | L3: FALSE | N3: FA | O3: Fire Alarm
A4: Y | B4: #0022 | C4: DPV | D4: 1.5 | E4: 1 | F4: WA | H4: Yes | I4: 45891 | J4: FALSE | K4: FALSE | L4: FALSE | N4: WA | O4: Sprinkler
A5: N | B5: #0024 | C5: DPV | D5: 1.5 | E5: 1 | F5: WA | G5: Yes | H5: Yes | I5: SEPT 12/25 | J5: FALSE | K5: FALSE | L5: FALSE | N5: EX | O5: Fire Extinguisher
A6: N | B6: #0025 | C6: DPV | D6: 1.5 | E6: 1 | F6: WA | G6: Yes | H6: Yes | I6: 45937 | J6: TRUE | K6: FALSE | L6: FALSE | N6: EM | O6: Emergency Lights
A7: N | B7: #0037 | C7: DPV | D7: 3 | E7: 2 | F7: WA | G7: Yes | H7: Yes | I7: active acct? | J7: FALSE | K7: FALSE | L7: FALSE | N7: BF | O7: Backflow
A8: Y | B8: #0060 | C8: DPV | D8: 3 | E8: 2 | F8: WA | G8: No | H8: Yes | I8: 45881 | J8: TRUE | K8: FALSE | L8: FALSE | N8: SM | O8: Smoke Control
A9: Y | B9: #0083 | C9: DPV | D9: 2 | E9: 2 | F9: WA | G9: Yes | H9: Yes | I9: 45898 | J9: TRUE | K9: FALSE | L9: FALSE
A10: Y | B10: #0146 | C10: DONE WITH ANNUAL | D10: 2 | E10: 2 | F10: FA, WA | G10: Yes | H10: Yes | I10: SEPT 26/25 | J10: FALSE | K10: FALSE | L10: FALSE | N10: TECH | O10: STAMPS HELD
A11: Y | B11: #0183 | C11: DONE WITH ANNUAL | D11: 1.5 | E11: 2 | F11: WA | G11: No | H11: Yes | I11: 45681 | J11: FALSE | K11: FALSE | L11: FALSE | N11: RS | O11: FA, WA, EX, EM
A12: Y | B12: #0190 | C12: DPV | D12: 3 | E12: 2 | F12: WA | G12: Yes | H12: No | I12: Apr.24/25 | J12: TRUE | K12: FALSE | L12: FALSE | N12: CG | O12: FA, WA, EX, EM, BF, SM
A13: Y | B13: #0240 | C13: DPV & Hydrant | D13: 3 | E13: 2 | F13: FA, WA | G13: Yes | H13: Yes | I13: Apr 14-16, 25 | J13: FALSE | K13: FALSE | L13: FALSE | M13: DPV done during annual Apr 14-16, 2025. Still need to schedule Hydrant service | N13: CY | O13: FA, WA, EX, EM
A14: Y | B14: #0244 | C14: DPV | D14: 2.5 | E14: 2 | F14: FA, WA | G14: No | H14: Yes | I14: 45898 | J14: TRUE | K14: FALSE | L14: FALSE | N14: MV | O14: FA, WA, EX, EM, BF & FITTER
B15: #0280 | C15: DPV | D15: 2 | E15: 2 | F15: WA | G15: No | H15: Yes | I15: CLOSED | J15: FALSE | K15: FALSE | L15: FALSE | N15: PM | O15: FA, WA, EX, EM
A16: Y | B16: #0297 | C16: DPV | D16: 1.5 | E16: 1 | F16: WA | G16: No | H16: Yes | I16: 45881 | J16: TRUE | K16: FALSE | L16: FALSE | N16: RD | O16: TRAINEE
A17: N | B17: #0308 | C17: DPV | D17: 1.5 | E17: 1 | F17: WA | G17: No | H17: Yes | I17: sept 17/25 | J17: TRUE | K17: FALSE | L17: FALSE | N17: GW | O17: FA, WA, EX, EM
A18: Y | B18: #0310 | C18: DONE WITH ANNUAL | D18: 3.5 | E18: 1 | F18: WA | G18: Yes | H18: Yes | I18: SEPT 9/25 | J18: FALSE | K18: FALSE | L18: FALSE | M18: Not done. No turbidity notice posted c/o CY Apr 17, 2025
B19: #0311 | C19: DPV | D19: 1.5 | E19: 1 | F19: WA | G19: Yes | H19: Yes | I19: CLOSED | J19: FALSE | K19: FALSE | L19: FALSE
A20: Y | B20: #0313 | C20: DPV & BF | D20: 4 | E20: 1 | F20: FA, WA, BF | G20: No | H20: No | I20: 45757 | J20: TRUE | K20: FALSE | L20: FALSE | N20: COLOUR CODE | R20: Responsibility
A21: Y | B21: #0326 | C21: DPV | D21: 3.5 | E21: 2 | F21: FA, WA | G21: No | H21: Yes | I21: 45876 | J21: TRUE | K21: FALSE | L21: TRUE | N21: DUE | O21: Needs To Be Scheduled | Q21: ## | R21: Scheduling Department
A22: N | B22: #0360 | C22: DPV | D22: 5 | E22: 2 | F22: FA, WA | G22: Yes | H22: Yes | I22: Sept 24/25 | J22: FALSE | K22: FALSE | L22: FALSE | N22: SCHEDULED | O22: Scheduled & Confirmed | Q22: ## | R22: Scheduling Department
A23: Y | B23: #0369 | C23: DPV | D23: 2 | E23: 1 | F23: WA | G23: Yes | H23: Yes | I23: 45869 | J23: TRUE | K23: FALSE | L23: TRUE | N23: SEMI-COMPLETE | O23: Revisit Required To Complete Service | Q23: ## | R23: Invoicing Department
A24: Y | B24: #0413 | C24: DPV | D24: 2 | E24: 1 | F24: WA | G24: Yes | H24: Yes | I24: 45888 | J24: TRUE | K24: FALSE | L24: FALSE | N24: COMPLETE | O24: Service 100% Complete | Q24: ## | R24: Invoicing Department
A25: Y | B25: #0437 | C25: DPV | D25: 2 | E25: 1 | F25: WA | G25: No | H25: Yes | I25: 45880 | J25: TRUE | K25: FALSE | L25: FALSE
B26: #0442 | C26: DPV | D26: 4 | E26: 1 | F26: WA | G26: Yes | H26: Yes | I26: CLOSED | J26: FALSE | K26: FALSE | L26: FALSE | N26: TOTAL LABOUR HOURS: | O26: =(D3*E3)+(D4*E4)+(D5*E5)+(D6*E6)+(D7*E7)+(D8*E8)+(D9*E9)+(D10*E10)+(D11*E11)+(D12*E12)+(D13*E13)+(D14*E14)+(D15*E15)+(D16*E16)+(D17*E17)+(D18*E18)+(D19*E19)+(D20*E20)+(D21*E21)+(D22*E22)+(D23*E23)+(D24*E24)+(D25*E25)+(D26*E26)+(D27*E27)+(D28*E28)+(D29*E29)+(D30*E30)+(D31*E31)+(D32*E32)+(D33*E33)+(D34*E34)+(D35*E35)+(D36*E36)+(D37*E37)+(D38*E38)+(D39*E39)+(D40*E40)+(D41*E41)+(D42*E42)+(D43*E43)+(D44*E44)+(D45*E45)+(D46*E46)+(D47*E47)+(D48*E48)+(D49*E49)+(D50*E50)+(D51*E51)+(D52*E52)+(D53*E53)+(D54*E54)+(D55*E55)+(D56*E56)+(D57*E57)+(D58*E58)+(D59*E59)+(D60*E60)+(D61*E61)+(D62*E62)+(D63*E63)+(D64*E64)+(D65*E65)+(D66*E66)+(D67*E67)+(D68*E68)+(D69*E69)+(D70*E70)+(D71*E71)+(D72*E72)+(D73*E73)+(D74*E74)+(D75*E75)+(D76*E76)+(D77*E77)+(D78*E78)+(D79*E79)+(D80*E80)+(D81*E81)+(D82*E82)+(D83*E83)+(D84*E84)+(D85*E85)+(D86*E86)+(D87*E87)+(D88*E88)+(D89*E89)+(D90*E90)+(D91*E91)+(D92*E92)+(D93*E93)+(D94*E94)+(D95*E95)+(D96*E96)+(D97*E97)+(D98*E98)+(D99*E99)+(D100*E100)+(D101*E101) -> 245.5
B27: #0445 | C27: DPV | D27: 2 | E27: 1 | F27: WA | G27: No | H27: No | I27: CLOSED | J27: FALSE | K27: FALSE | L27: FALSE
A28: N | B28: #0460 | C28: DPV | D28: 3 | E28: 2 | F28: FA, WA | G28: No | H28: Yes | I28: Sept 25/25 | J28: FALSE | K28: FALSE | L28: FALSE
A29: Y | B29: #0462 | C29: DONE WITH ANNUAL | D29: 1.5 | E29: 1 | F29: WA | G29: No | H29: Yes | I29: 45792 | J29: FALSE | K29: FALSE | L29: FALSE
A30: N | B30: #0509 | C30: DPV | D30: 2 | E30: 1 | F30: WA | G30: No | H30: No | I30: CLOSED | J30: FALSE | K30: FALSE | L30: FALSE
A31: Y | B31: #0512 | C31: DPV | D31: 2.5 | E31: 1 | F31: WA | G31: Yes | H31: Yes | I31: 45880 | J31: TRUE | K31: FALSE | L31: FALSE
A32: N | B32: #0514 | C32: DPV | D32: 2 | E32: 1 | F32: WA | G32: Yes | H32: Yes | I32: 45434 | J32: FALSE | K32: FALSE | L32: FALSE
A33: N | B33: #0515 | C33: DPV | D33: 4.5 | E33: 2 | F33: WA | G33: Yes | H33: Yes | I33: 45484 | J33: FALSE | K33: FALSE | L33: FALSE
A34: Y | B34: #0516 | C34: DPV | D34: 4 | E34: 2 | F34: WA | G34: Yes | H34: Yes | I34: 45758 | J34: TRUE | K34: TRUE | L34: TRUE
A35: Y | B35: #0518 | C35: DPV | D35: 8 | E35: 2 | F35: WA | G35: Yes | H35: No | I35: 45883 | J35: TRUE | K35: FALSE | L35: FALSE
B36: #0520 | C36: DPV | D36: 16 | E36: 2 | F36: WA | G36: No | H36: Yes | I36: CLOSED ACCOUNT | J36: FALSE | K36: FALSE | L36: FALSE
A37: Y | B37: #0523 | C37: DPV | D37: 2 | E37: 1 | F37: WA | G37: Yes | H37: No | I37: 45880 | J37: TRUE | K37: FALSE | L37: FALSE
A38: Y | B38: #0529 | C38: DPV | D38: 2 | E38: 1 | F38: WA | G38: Yes | H38: No | I38: 45889 | J38: TRUE | K38: FALSE | L38: FALSE
A39: Y | B39: #0533 | C39: DPV | D39: 4 | E39: 2 | F39: FA, WA | G39: Yes | H39: Yes | I39: 45889 | J39: TRUE | K39: FALSE | L39: FALSE
A40: Y | B40: #0570 | C40: DPV | D40: 2 | E40: 1 | F40: WA | G40: Yes | H40: Yes | I40: 45890 | J40: TRUE | K40: FALSE | L40: FALSE
...

Sheet MAY
B1: MAY | K1: TECH REPORTS
A2: ANNUAL AGREEMENT SIGNED? | B2: FILE # | C2: CITY | D2: SERVICE TYPE | E2: # OF HRS REQ | F2: # OF TECHS | G2: STAMP/S REQ | H2: CONTRACTOR | I2: KEYS | J2: LAST COMPLETED | K2: REPORT IN EMAIL | L2: REPAIRS NEEDED | M2: REPORT COMPLETE | N2: ANNUAL REPORT SENT | O2: ASA sent | Q2: STAMP | R2: DEFINITION
A3: FALSE | B3: #0001 | C3: Vancouver | D3: Annual | E3: 3 | F3: 2 | G3: FA, EX, EM | H3: No | I3: No | J3: 45791 | K3: TRUE | L3: TRUE | M3: TRUE | N3: TRUE | O3: TRUE | Q3: FA | R3: Fire Alarm
A4: FALSE | B4: #0013 | C4: Surrey | D4: Annual | E4: 1 | F4: 1 | G4: EX, EM | H4: No | I4: No | J4: 45884 | K4: TRUE | L4: FALSE | M4: TRUE | N4: TRUE | O4: FALSE | P4: Moved to Aug tab | Q4: WA | R4: Sprinkler | U4: sent email (service schedule) aug 1st, 2025
A5: FALSE | B5: #0059 | C5: Vancouver | D5: ANNUAL | E5: 2 | F5: 1 | G5: EX, EM | H5: No | I5: No | J5: CLOSED | K5: FALSE | L5: FALSE | M5: FALSE | N5: FALSE | O5: FALSE | Q5: EX | R5: Fire Extinguisher | U5: sent email (service schedule) aug 1st, 2025
A6: FALSE | B6: #0070 | C6: Richmond | D6: DPV, BF, Fire Pump | E6: 4.5 | F6: 2 | G6: FA, WA, BF | H6: Yes | I6: Yes | J6: 45798 | K6: TRUE | L6: TRUE | M6: TRUE | N6: TRUE | O6: TRUE | P6: Please find the attached 2025 annual inspection report and after service advisory for this property. | Q6: EM | R6: Emergency Lights | U6: Remark: | V6: #0070-1 | W6: Tank due for HST service in May, 2024 as per Pat @ Great West. Job starts at 7:00am. Please confirm the HST charges with Pat. Dec 18/23 LM
A7: FALSE | B7: #0070-1 | C7: Richmond | D7: Kitchen | E7: 1 | F7: 1 | G7: FA | H7: Yes | I7: No | J7: 45797 | K7: TRUE | L7: FALSE | M7: FALSE | N7: FALSE | O7: FALSE | Q7: BF | R7: Backflow
A8: FALSE | B8: #0078 | C8: Vancouver | D8: Annual | E8: 3.5 | F8: 2 | G8: FA, EX, EM, WA | H8: No | I8: No | J8: 45877 | K8: TRUE | L8: TRUE | M8: TRUE | N8: TRUE | O8: FALSE | P8: Moved to Aug tab | Q8: SM | R8: Smoke Control
A9: FALSE | B9: #0086 | C9: Vancouver | D9: Annual | E9: 2 | F9: 2 | G9: FA, EX, EL | J9: 45884 | K9: FALSE | L9: FALSE | M9: FALSE | N9: FALSE | O9: FALSE | P9: No reply | U9: Sent email(service schedule) Aug 1st, 2025
A10: FALSE | B10: #0088 | C10: Vancouver | D10: Annual | E10: 2.5 | F10: 2 | G10: FA, EX, WA, BF | H10: No | I10: No | J10: 45814 | K10: TRUE | L10: TRUE | M10: TRUE | N10: TRUE | O10: TRUE | U10: 2025 Remark: | V10: #0088 | W10: Please also replace 15 sprinkler heads per ASA approved by Susan.
A11: TRUE | B11: #0209 | C11: Vancouver | D11: DPV & BF | E11: 1.5 | F11: 2 | G11: WA, BF | H11: Yes | I11: No | J11: 45882 | K11: TRUE | L11: FALSE | M11: FALSE | N11: FALSE | O11: FALSE | P11: BF done during annaul in Jan, 2025 | Q11: TECH | R11: STAMPS HELD
A12: FALSE | B12: #0210 | C12: Vancouver | D12: DPV & BF | E12: 2 | F12: 1 | G12: WA, BF | H12: Yes | I12: No | J12: 45783 | K12: TRUE | L12: TRUE | M12: TRUE | N12: TRUE | Q12: RS | R12: FA, WA, EX, EM
A13: FALSE | B13: #0219 | C13: Vancouver | D13: Annual | E13: 1.5 | F13: 1 | G13: EX, EM | H13: No | I13: No | J13: 45806 | K13: TRUE | L13: TRUE | M13: TRUE | N13: TRUE | O13: TRUE | Q13: CG | R13: FA, WA, EX, EM, BF, SM
A14: FALSE | B14: #0238 | C14: Vancouver | D14: Spring & BF | E14: 2 | F14: 1 | G14: WA, BF | H14: No | I14: Yes | J14: 45776 | K14: TRUE | L14: FALSE | M14: FALSE | N14: FALSE | O14: FALSE | Q14: CY | R14: FA, WA, EX, EM
A15: TRUE | B15: #0268 | C15: Vancouver | D15: Annual | E15: 8 | F15: 2 | G15: FA, WA, EX, EM, BF | H15: Yes | I15: Yes | J15: 45813 | K15: TRUE | L15: TRUE | M15: TRUE | N15: TRUE | O15: TRUE | Q15: MV | R15: FA, WA, EX, EM, BF & FITTER | U15: 0.01
A16: FALSE | B16: #0295 | C16: Vancouver | D16: Annual | E16: 3 | F16: 1 | G16: EX, EM | H16: No | I16: No | J16: 45813 | K16: TRUE | L16: TRUE | M16: TRUE | N16: TRUE | O16: TRUE | Q16: PM | R16: FA, WA, EX, EM
A17: FALSE | B17: #0302 | C17: Vancouver | D17: Annual & Kitchen | E17: 1 | F17: 1 | G17: EX, | H17: Yes | I17: Yes | J17: 45799 | K17: TRUE | L17: TRUE | M17: TRUE | N17: TRUE | O17: TRUE | Q17: RD | R17: BF
A18: FALSE | B18: #0309 | C18: Vancouver | D18: Annual | E18: 12 | F18: 2 | G18: FA, WA, EX, EM | H18: Yes | I18: Yes | J18: June 5 & 6/25 | K18: TRUE | L18: TRUE | M18: TRUE | N18: TRUE | O18: TRUE | Q18: GW | R18: FA, WA, EX, EM
A19: FALSE | B19: #0318 | C19: Richmond | D19: Spring | E19: 2.5 | F19: 2 | G19: FA, WA | H19: Yes | I19: Yes | J19: CLOSED | K19: FALSE | L19: FALSE | M19: FALSE | N19: FALSE | O19: FALSE | Q19: TS | R19: EX, EM, BF
A20: FALSE | B20: #0325 | C20: Vancouver | D20: Annual | E20: 1.5 | F20: 1 | G20: EX, EM | H20: No | I20: No | J20: 45819 | K20: TRUE | L20: FALSE | M20: TRUE | N20: TRUE | O20: FALSE
A21: FALSE | B21: #0325-1 | C21: Vancouver | D21: Annual | E21: 0.5 | F21: 1 | G21: EX | H21: No | I21: No | J21: 45819 | K21: TRUE | L21: FALSE | M21: TRUE | N21: TRUE | O21: FALSE
A22: FALSE | B22: #0331 | C22: New Westminister | D22: Annual | E22: 24 | F22: 2 | G22: FA, WA, EX, EM, BF | H22: Yes | I22: Yes | J22: June 11,12,13/25 | K22: TRUE | L22: TRUE | M22: TRUE | N22: TRUE | O22: TRUE
A23: TRUE | B23: #0381 | C23: Vancouver | D23: Annual | E23: 2 | F23: 2 | G23: FA, EX, EM | H23: No | I23: No | J23: Moved to August | K23: TRUE | L23: TRUE | M23: TRUE | N23: TRUE | O23: FALSE | Q23: COLOUR CODE | U23: Responsibility
A24: FALSE | B24: #0400 | C24: Burnaby | D24: Spring & Kitchen | E24: 6 | F24: 2 | G24: FA, WA | H24: Yes | I24: Yes | J24: 45811 | K24: TRUE | L24: TRUE | M24: TRUE | N24: TRUE | O24: TRUE | Q24: DUE | R24: Needs To Be Scheduled | T24: ## | U24: Scheduling Department
A25: TRUE | B25: #0417 | C25: Vancouver | D25: Annual | E25: 8 | F25: 2 | G25: FA, WA, EX, EM | H25: Yes | I25: Yes | J25: May 12 & July 23, 25 | K25: TRUE | L25: FALSE | M25: FALSE | N25: FALSE | O25: FALSE | Q25: SCHEDULED | R25: Scheduled & Confirmed | T25: ## | U25: Scheduling Department
A26: FALSE | B26: #0418 | C26: Vancouver | D26: Annual | E26: 3 | F26: 1 | G26: FA, WA, EX, EM, BF | H26: No | I26: No | J26: 45817 | K26: TRUE | L26: TRUE | M26: TRUE | N26: TRUE | O26: TRUE | P26: Moved to June tab | Q26: SEMI-COMPLETE | R26: Revisit Required To Complete Service | T26: ## | U26: Invoicing Department
A27: FALSE | B27: #0421 | C27: Vancouver | D27: Annual | E27: 5 | F27: 2 | G27: FA, WA, EX, EM, BF | H27: Yes | I27: Yes | J27: 45806 | K27: TRUE | L27: TRUE | M27: TRUE | N27: TRUE | O27: TRUE | Q27: COMPLETE | R27: Service 100% Complete | T27: ## | U27: Invoicing Department
A28: FALSE | B28: #0461 | C28: Vancouver | D28: Spring & BF | E28: 3 | F28: 2 | G28: FA, WA, BF | H28: No | I28: Yes | J28: CLOSED | K28: FALSE | L28: FALSE | M28: FALSE | N28: FALSE | O28: FALSE
A29: FALSE | B29: #0462 | C29: Vancouver | D29: Annual minus DPV | E29: 4.5 | F29: 2 | G29: FA, EX, EM | H29: Yes | I29: Yes | J29: 45792 | K29: TRUE | L29: TRUE | M29: TRUE | N29: TRUE | O29: TRUE
A30: FALSE | B30: #0490 | C30: Vancouver | D30: Annual | E30: 5 | F30: 2 | G30: FA, WA, EX, EM | H30: Yes | I30: No | J30: 45797 | K30: TRUE | L30: TRUE | M30: TRUE | N30: TRUE | O30: TRUE
A31: TRUE | B31: #0491 | C31: Vancouver | D31: Annual | E31: 4 | F31: 2 | G31: FA, WA, EX, EM | H31: No | I31: No | J31: 45798 | K31: TRUE | L31: TRUE | M31: TRUE | N31: TRUE | O31: TRUE | Q31: TOTAL LABOUR HOURS: | R31: =(E3*F3)+(E4*F4)+(E5*F5)+(E6*F6)+(E7*F7)+(E9*F9)+(E10*F10)+(E11*F11)+(E12*F12)+(E13*F13)+(E14*F14)+(E15*F15)+(E17*F17)+(E18*F18)+(E19*F19)+(E20*F20)+(E21*F21)+(E23*F23)+(E24*F24)+(E25*F25)+(E26*F26)+(E27*F27)+(E28*F28)+(E30*F30)+(E31*F31)+(E32*F32)+(E33*F33)+(E34*F34)+(E35*F35)+(E36*F36)+(E37*F37)+(E38*F38)+(JAN!E26*JAN!F26)+(E40*F40)+(E41*F41)+(E42*F42)+(E43*F43)+(E44*F44)+(E45*F45)+(E46*F46)+(E47*F47)+(E48*F48)+(E49*F49)+(E51*F51)+(E52*F52)+(E53*F53)+(E55*F55)+(E56*F56)+(E57*F57)+(E58*F58)+(F59*G59)+(E60*F60)+(E61*F61)+(E62*F62)+(E63*F63)+(E64*F64)+(E65*F65)+(E66*F66)+(E67*F67)+(E68*F68)+(E69*F69)+(E70*F70)+(E71*F71)+(E72*F72)+(E73*F73)+(E74*F74)+(E75*F75)+(E76*F76)+(E77*F77)+(E78*F78)+(E79*F79)+(E80*F80)+(E81*F81)+(E82*F82)+(E83*F83)+(E84*F84)+(E85*F85)+(E86*F86)+(E87*F87)+(E88*F88)+(E89*F89)+(E90*F90)+(E91*F91)+(E92*F92)+(E93*F93)+(E94*F94)+(E95*F95)+(E96*F96)+(E97*F97)+(E98*F98)+(E99*F99)+(E100*F100)+(E101*F101)+(E102*F102)+(E103*F103)+(E104*F104)+(E105*F105)+(E106*F106) -> #VALUE!
A32: FALSE | B32: #0528 | C32: Burnaby | D32: Annual | E32: 3 | F32: 2 | G32: FA, WA, EX, EM | H32: No | I32: No | J32: 45801 | K32: FALSE | L32: FALSE | M32: FALSE | N32: FALSE | O32: FALSE | P32: No reply
A33: FALSE | B33: #0545 | C33: Vancouver | D33: Annual | E33: 1 | F33: 1 | G33: EX, EM | H33: No | I33: No | J33: 45807 | K33: TRUE | L33: FALSE | M33: TRUE | N33: TRUE | O33: FALSE | Q33: TOTAL AVAILABLE LABOUR HOURS IN THE MONTH | T33: 708 | V33: Based on 4 Techs in the field. Derived by (days of month divided by 7 then times by 5) x (number of techs times by 8)
A34: TRUE | B34: #0548 | C34: Vancouver | D34: Annual | E34: 4 | F34: 2 | G34: FA, WA, EX, EM, BF | H34: No | I34: No | J34: 45807 | K34: TRUE | L34: TRUE | M34: TRUE | N34: TRUE | O34: TRUE
A35: TRUE | B35: #0557 | C35: Vancouver | D35: Annual | E35: 1.5 | F35: 1 | G35: EX, EM | H35: No | I35: No | J35: Sep 5, 25 | K35: TRUE | L35: FALSE | M35: TRUE | N35: TRUE | O35: FALSE | P35: Moved to Sept tab | Q35: REMAINING LABOUR HRS | S35: =T33-R31 -> #VALUE! | V35: Account for Spring service hours
A36: FALSE | B36: #0577 | C36: Vancouver | D36: Annual | E36: 5 | F36: 2 | G36: FA, WA, EX, EM, BF | H36: Yes | I36: No | J36: DISCONTINUED SERVICE | K36: FALSE | L36: FALSE | M36: FALSE | N36: FALSE | O36: FALSE
A37: FALSE | B37: #0578 | C37: Vancouver | D37: Annual | E37: 6 | F37: 2 | G37: FA, WA, EX, EM, BF | H37: Yes | I37: Yes | J37: DISCONTINUED SERVICE | K37: FALSE | L37: FALSE | M37: FALSE | N37: FALSE | O37: FALSE
A38: FALSE | B38: #0579 | C38: Vancouver | D38: Annual | E38: 6 | F38: 2 | G38: FA, WA, EX, EM, BF | H38: Yes | I38: Yes | J38: DISCONTINUED SERVICE | K38: FALSE | L38: FALSE | M38: FALSE | N38: FALSE | O38: FALSE
A40: TRUE | B40: #0598 | C40: Richmond | D40: Annual | E40: 24 | F40: 2 | G40: FA, WA, EX, EM, BF | H40: Yes | I40: No | J40: June 2-4, 25 | K40: TRUE | L40: TRUE | M40: TRUE | N40: TRUE | O40: TRUE
A41: FALSE | B41: #0602 | C41: Vancouver | D41: Annual | E41: 6 | F41: 2 | G41: FA, WA, EX, EM, BF | H41: No | I41: No | J41: 45799 | K41: TRUE | L41: TRUE | M41: TRUE | N41: TRUE | O41: TRUE
...

Sheet JUN
B1: JUNE | K1: TECH REPORTS
A2: ANNUAL AGREEMENT SIGNED? | B2: FILE # | C2: CITY | D2: SERVICE TYPE | E2: # OF HRS REQ | F2: # OF TECHS | G2: STAMP/S REQ | H2: CONTRACTOR | I2: KEYS | J2: LAST COMPLETED | K2: REPORT IN EMAIL | L2: REPAIRS NEEDED | M2: REPORT COMPLETE | N2: ANNUAL REPORT SENT | O2: ASA Sent | Q2: STAMP | S2: DEFINITION
A3: FALSE | B3: #0073 | C3: Vancouver | D3: Annual | E3: 32 | F3: 2 | G3: FA, EX, EM, WA, BF | H3: Yes | I3: Yes | J3: Moved to April | K3: TRUE | L3: TRUE | M3: TRUE | N3: TRUE | O3: TRUE | Q3: FA | S3: Fire Alarm
A4: FALSE | B4: #0127 | C4: Vancouver | D4: Annual | E4: 2 | F4: 2 | G4: FA, EX, EM | H4: No | I4: No | J4: Moved to April | K4: FALSE | L4: FALSE | M4: FALSE | N4: FALSE | O4: FALSE | Q4: WA | S4: Sprinkler
A5: FALSE | B5: #0148 | C5: Vancouver | D5: Annual | E5: 2.5 | F5: 1 | G5: EX | H5: No | I5: No | J5: Moved to Sept | K5: TRUE | L5: FALSE | M5: TRUE | N5: TRUE | O5: FALSE | Q5: EX | S5: Fire Extinguisher
A6: FALSE | B6: #0149 | C6: Vancouver | D6: Annual | E6: 2 | F6: 1 | G6: FA, EX | H6: No | I6: No | J6: Moved to Sept | K6: TRUE | L6: FALSE | M6: TRUE | N6: TRUE | O6: FALSE | Q6: EM | S6: Emergency Lights
A7: FALSE | B7: #0225 | C7: Vancouver | D7: Annual | E7: 8 | F7: 2 | G7: FA, WA, EX, EM, BF | H7: Yes | I7: Yes | J7: 45854 | K7: TRUE | L7: TRUE | M7: TRUE | N7: TRUE | O7: FALSE | Q7: BF | S7: Backflow
A8: FALSE | B8: #0225-1 | C8: Vancouver | D8: Annual | E8: 1.5 | F8: 2 | G8: EX, EM, BF | H8: Yes | I8: Yes | J8: 45854 | K8: TRUE | L8: TRUE | M8: TRUE | N8: TRUE | O8: FALSE | Q8: SM | S8: Smoke Control
A9: FALSE | B9: #0225-2 | C9: Vancouver | D9: Annual | E9: 1.5 | F9: 2 | G9: EX, EM, BF | H9: Yes | I9: Yes | J9: 45854 | K9: TRUE | L9: TRUE | M9: TRUE | N9: TRUE | O9: TRUE
A10: FALSE | B10: #0271 | C10: Vancouver | D10: Kitchen | E10: 1 | F10: 1 | G10: FA | H10: Yes | I10: Yes | K10: FALSE | L10: FALSE | M10: FALSE | N10: FALSE | O10: FALSE | Q10: TECH | S10: STAMPS HELD
A11: FALSE | B11: #0278 | C11: Vancouver | D11: Annual | E11: 16 | F11: 2 | G11: FA, WA, EX, EM, BF | H11: Yes | I11: Yes | J11: DENIED SERVICE | K11: FALSE | L11: FALSE | M11: FALSE | N11: FALSE | O11: FALSE | Q11: RS | S11: FA, WA, EX, EM
A12: FALSE | B12: #0298 | C12: North Vancouver | D12: Annual | J12: 45835 | K12: TRUE | L12: TRUE | M12: TRUE | N12: TRUE | O12: TRUE | Q12: CG | S12: FA, WA, EX, EM, BF, SM
A13: TRUE | B13: #0301 | C13: Vancouver | D13: Kitchen | E13: 1 | F13: 1 | G13: FA | H13: Yes | I13: Yes | J13: 45849 | K13: TRUE | L13: FALSE | M13: FALSE | N13: FALSE | O13: FALSE | Q13: CY | S13: FA, WA, EX, EM
A14: FALSE | B14: #0323 | C14: Vancouver | D14: Kitchens | E14: 2 | F14: 1 | G14: FA | H14: Yes | I14: Yes | J14: 45783 | K14: TRUE | L14: FALSE | M14: FALSE | N14: FALSE | O14: FALSE | Q14: MV | S14: FA, WA, EX, EM, BF & FITTER
A15: FALSE | B15: #0349 | C15: Vancouver | D15: Annual | E15: 2 | F15: 2 | G15: EX, EM, BF | H15: No | I15: No | J15: 45835 | K15: TRUE | L15: FALSE | M15: TRUE | N15: TRUE | O15: FALSE | Q15: PM | S15: FA, WA, EX, EM
A16: TRUE | B16: #0357 | C16: Vancouver | D16: Annual, Fire Pump & Kitchen | E16: 20 | F16: 2 | G16: FA, WA, EX, EM, BF | H16: Yes | I16: No | J16: Jun 24-26 + Jul 9, 25 | K16: TRUE | L16: TRUE | M16: TRUE | N16: TRUE | O16: TRUE | Q16: RD | S16: TRAINEE
A17: FALSE | B17: #0391 | C17: Vancouver | D17: Annual | E17: 4 | F17: 2 | G17: FA, WA, EX, EM, BF | H17: No | I17: Yes | J17: 45847 | K17: TRUE | L17: TRUE | M17: TRUE | N17: TRUE | O17: TRUE | Q17: TS | S17: EX, EM, BF
A18: FALSE | B18: #0392 | C18: Vancouver | D18: Annual | E18: 16 | F18: 2 | G18: FA, WA, EX, EM | H18: Yes | I18: Yes | J18: June 9 & 10/25 | K18: TRUE | L18: TRUE | M18: TRUE | N18: TRUE | O18: TRUE
A19: FALSE | B19: #0414 | C19: Vancouver | D19: Annual | E19: 1 | F19: 1 | G19: EX, EM | H19: No | I19: No | J19: 45848 | K19: TRUE | L19: FALSE | M19: TRUE | N19: TRUE | O19: FALSE
A20: FALSE | B20: #0420 | C20: Vancouver | D20: Annual | E20: 12 | F20: 2 | G20: FA, WA, EX, EM | H20: Yes | I20: Yes | J20: 45852 | K20: TRUE | L20: TRUE | M20: TRUE | N20: TRUE | O20: TRUE | Q20: COLOUR CODE | V20: Responsibility
A21: FALSE | B21: #0422 | C21: Vancouver | D21: Annual & Suppression | E21: 2.5 | F21: 2 | G21: FA, EX, EM | H21: Yes | I21: No | J21: 45848 | K21: TRUE | L21: FALSE | M21: TRUE | N21: TRUE | O21: FALSE | Q21: DUE | S21: Needs To Be Scheduled | U21: ## | V21: Scheduling Department
A22: FALSE | B22: #0444 | C22: Vancouver | D22: Dry SPRING & Wet Sprinkler | E22: 3 | F22: 1 | G22: WA | H22: No | I22: No | J22: 45847 | K22: TRUE | L22: FALSE | M22: FALSE | N22: FALSE | O22: FALSE | Q22: SCHEDULED | S22: Scheduled & Confirmed | U22: ## | V22: Scheduling Department
A23: FALSE | B23: #0447 | C23: Vancouver | D23: Spring & Kitchen | E23: 4.5 | F23: 1 | G23: FA, WA | H23: Yes | I23: Yes | J23: Jun 26 & Jul 7, 25 | K23: TRUE | L23: FALSE | M23: FALSE | N23: FALSE | O23: FALSE | Q23: SEMI-COMPLETE | S23: Revisit Required To Complete Service | U23: ## | V23: Invoicing Department
